<?xml version="1.0"?>

<robot xmlns="http://drake.mit.edu"
 xmlns:xsi="http://www.w3.org/2001/XMLSchema-instance"
 xsi:schemaLocation="http://drake.mit.edu ../../doc/drakeURDF.xsd" name="BoxValkyrie">
  <link name="core">
    <inertial>
      <mass value="1.0"/>
      <origin rpy="0 0 0" xyz="0 0 0"/>
      <inertia ixx="1.0" iyy="1.0" izz="1.0" ixy="0.0" ixz="0.0" iyz="0.0"/>
    </inertial>
    <visual>
      <origin xyz="0 0 0.025"/>
      <geometry>
        <box size="0.4 0.05 0.55"/>
      </geometry>
    </visual>
  </link>

  <link name="lf_dummy">
    <inertial>
      <mass value="0.0"/>
      <origin rpy="0 0 0" xyz="0 0 0"/>
      <inertia ixx="0.0" iyy="0.0" izz="0.0" ixy="0.0" ixz="0.0" iyz="0.0"/>
    </inertial>
    <visual>
      <geometry>
        <sphere radius="0.025"/>
      </geometry>
    </visual>
  </link>

  <link name="lf">
    <inertial>
      <mass value="0.2"/>
      <origin rpy="0 0 0" xyz="0 0 0"/>
      <inertia ixx="1.0" iyy="1.0" izz="1.0" ixy="0.0" ixz="0.0" iyz="0.0"/>
    </inertial>
    <visual>
      <geometry>
        <sphere radius="0.05"/>
      </geometry>
    </visual>
  </link>

  <joint name="core_to_lf_rotation" type="revolute">
    <parent link="core"/>
    <child link="lf_dummy"/>
    <origin xyz="0 0 -0.2"/>
    <axis xyz="0 1 0"/>
    <limit lower="-0.785398" upper="0.785398" velocity="10" effort="40"/>
  </joint>

  <joint name="core_to_lf_extension" type="prismatic">
    <parent link="lf_dummy"/>
    <child link="lf"/>
    <origin xyz="0 0 0"/>
    <axis xyz="0 0 -1"/>
    <limit lower="0.4" upper="0.9" velocity="10" effort="40"/>
  </joint>


</robot>


