<?xml version="1.0"?>

<robot name="BoxAtlas">
  <link name="root">
  </link>

  <link name="floor">
    <visual>
      <origin xyz="0.5 0 -0.05"/>
      <geometry>
        <box size="3 1 0.1"/>
      </geometry>
    </visual>
    <collision>
      <origin xyz="0.5 0 -0.05"/>
      <geometry>
        <box size="3 1 0.1"/>
      </geometry>
    </collision>
    <collision>
      <geometry>
        <plane normal="0 0 1"/>
      </geometry>
    </collision>
  </link>

  <joint name="root_to_floor" type="fixed">
    <parent link="root"/>
    <child link="floor"/>
  </joint>

  <link name="wall">
    <visual>
      <origin xyz="-1.05 0 1"/>
      <geometry>
        <box size="0.1 1 2.2"/>
      </geometry>
    </visual>
    <collision>
      <origin xyz="-1.05 0 1"/>
      <geometry>
        <box size="0.1 1 2"/>
      </geometry>
    </collision>
    <collision>
      <origin xyz="-1 0 1"/>
      <geometry>
        <plane normal="1 0 0"/>
      </geometry>
    </collision>
  </link>

  <joint name="root_to_wall" type="fixed">
    <parent link="root"/>
    <child link="wall"/>
  </joint>

  <link name="core">
    <inertial>
      <mass value="1.0"/>
      <origin rpy="0 0 0" xyz="0 0 0"/>
      <inertia ixx="0.025" iyy="0.039" izz="0.014" ixy="0.0" ixz="0.0" iyz="0.0"/>
    </inertial>
    <visual>
      <origin xyz="0 0 0.025"/>
      <geometry>
        <box size="0.4 0.05 0.55"/>
      </geometry>
    </visual>
  </link>

  <joint name="floating_base" type="planar">
    <axis xyz="0 -1 0"/>
    <parent link="root"/>
    <child link="core"/>
  </joint>

  <link name="rh_dummy">
    <inertial>
      <mass value="0.0"/>
      <origin rpy="0 0 0" xyz="0 0 0"/>
      <inertia ixx="0.0" iyy="0.0" izz="0.0" ixy="0.0" ixz="0.0" iyz="0.0"/>
    </inertial>
    <visual>
      <geometry>
        <sphere radius="0.05"/>
      </geometry>
    </visual>
    <visual>
      <origin xyz="0.1875 0 0" rpy="0 1.5707963267948966 0"/>
      <geometry>
        <cylinder radius="0.03" length="0.375"/>
      </geometry>
    </visual>
  </link>

  <link name="rh">
    <inertial>
      <mass value="0.05"/>
      <origin rpy="0 0 0" xyz="0 0 0"/>
      <inertia ixx="0.025" iyy="0.039" izz="0.014" ixy="0.0" ixz="0.0" iyz="0.0"/>
    </inertial>
    <visual>
      <geometry>
        <sphere radius="0.025"/>
      </geometry>
    </visual>
    <visual>
      <origin xyz="-0.1875 0 0" rpy="0 1.5707963267948966 0"/>
      <geometry>
        <cylinder radius="0.02" length="0.375"/>
      </geometry>
    </visual>
    <collision>
      <geometry>
        <sphere radius="0"/>
      </geometry>
    </collision>
  </link>

  <joint name="core_to_rh_rotation" type="revolute">
    <parent link="core"/>
    <child link="rh_dummy"/>
    <origin xyz="0.25 0 0.30"/>
    <axis xyz="0 -1 0"/>
    <limit lower="-1.5708" upper="0.1" velocity="100" effort="2"/>
  </joint>

  <joint name="core_to_rh_extension" type="prismatic">
    <parent link="rh_dummy"/>
    <child link="rh"/>
    <origin xyz="0 0 0"/>
    <axis xyz="1 0 0"/>
    <limit lower="0.375" upper="0.75" velocity="100" effort="2"/>
  </joint>

  <link name="lh_dummy">
    <inertial>
      <mass value="0.0"/>
      <origin rpy="0 0 0" xyz="0 0 0"/>
      <inertia ixx="0.0" iyy="0.0" izz="0.0" ixy="0.0" ixz="0.0" iyz="0.0"/>
    </inertial>
    <visual>
      <geometry>
        <sphere radius="0.05"/>
      </geometry>
    </visual>
    <visual>
      <origin xyz="-0.1875 0 0" rpy="0 1.5707963267948966 0"/>
      <geometry>
        <cylinder radius="0.03" length="0.375"/>
      </geometry>
    </visual>
  </link>

  <link name="lh">
    <inertial>
      <mass value="0.05"/>
      <origin rpy="0 0 0" xyz="0 0 0"/>
      <inertia ixx="0.025" iyy="0.039" izz="0.014" ixy="0.0" ixz="0.0" iyz="0.0"/>
    </inertial>
    <visual>
      <geometry>
        <sphere radius="0.025"/>
      </geometry>
    </visual>
    <visual>
      <origin xyz="0.1875 0 0" rpy="0 1.5707963267948966 0"/>
      <geometry>
        <cylinder radius="0.02" length="0.375"/>
      </geometry>
    </visual>
    <collision>
      <geometry>
        <sphere radius="0"/>
      </geometry>
    </collision>
  </link>

  <joint name="core_to_lh_rotation" type="revolute">
    <parent link="core"/>
    <child link="lh_dummy"/>
    <origin xyz="-0.25 0 0.30"/>
    <axis xyz="0 1 0"/>
    <limit lower="-1.5708" upper="0.1" velocity="100" effort="2"/>
  </joint>

  <joint name="core_to_lh_extension" type="prismatic">
    <parent link="lh_dummy"/>
    <child link="lh"/>
    <origin xyz="0 0 0"/>
    <axis xyz="-1 0 0"/>
    <limit lower="0.375" upper="0.75" velocity="100" effort="2"/>
  </joint>

  <link name="rf_dummy">
    <inertial>
      <mass value="0.0"/>
      <origin rpy="0 0 0" xyz="0 0 0"/>
      <inertia ixx="0.0" iyy="0.0" izz="0.0" ixy="0.0" ixz="0.0" iyz="0.0"/>
    </inertial>
    <visual>
      <geometry>
        <sphere radius="0.05"/>
      </geometry>
    </visual>
    <visual>
      <origin xyz="0 0 -0.225" rpy="0 0 0"/>
      <geometry>
        <cylinder radius="0.03" length="0.45"/>
      </geometry>
    </visual>
  </link>

  <link name="rf">
    <inertial>
      <mass value="0.2"/>
      <origin rpy="0 0 0" xyz="0 0 0"/>
      <inertia ixx="0.025" iyy="0.039" izz="0.014" ixy="0.0" ixz="0.0" iyz="0.0"/>
    </inertial>
    <visual>
      <geometry>
        <sphere radius="0.025"/>
      </geometry>
    </visual>
    <visual>
      <origin xyz="0 0 0.225" rpy="0 0 0"/>
      <geometry>
        <cylinder radius="0.02" length="0.45"/>
      </geometry>
    </visual>
    <collision>
      <geometry>
        <sphere radius="0"/>
      </geometry>
    </collision>
  </link>

  <joint name="core_to_rf_rotation" type="revolute">
    <parent link="core"/>
    <child link="rf_dummy"/>
    <origin xyz="0.20 0 -0.25"/>
    <axis xyz="0 -1 0"/>
    <limit lower="-0.05" upper="0.785398" velocity="100" effort="10"/>
  </joint>

  <joint name="core_to_rf_extension" type="prismatic">
    <parent link="rf_dummy"/>
    <child link="rf"/>
    <origin xyz="0 0 0"/>
    <axis xyz="0 0 -1"/>
    <limit lower="0.45" upper="0.9" velocity="100" effort="20"/>
  </joint>

  <link name="lf_dummy">
    <inertial>
      <mass value="0.0"/>
      <origin rpy="0 0 0" xyz="0 0 0"/>
      <inertia ixx="0.0" iyy="0.0" izz="0.0" ixy="0.0" ixz="0.0" iyz="0.0"/>
    </inertial>
    <visual>
      <geometry>
        <sphere radius="0.05"/>
      </geometry>
    </visual>
    <visual>
      <origin xyz="0 0 -0.225" rpy="0 0 0"/>
      <geometry>
        <cylinder radius="0.03" length="0.45"/>
      </geometry>
    </visual>
  </link>

  <link name="lf">
    <inertial>
      <mass value="0.2"/>
      <origin rpy="0 0 0" xyz="0 0 0"/>
      <inertia ixx="0.025" iyy="0.039" izz="0.014" ixy="0.0" ixz="0.0" iyz="0.0"/>
    </inertial>
    <visual>
      <geometry>
        <sphere radius="0.025"/>
      </geometry>
    </visual>
    <visual>
      <origin xyz="0 0 0.225" rpy="0 0 0"/>
      <geometry>
        <cylinder radius="0.02" length="0.45"/>
      </geometry>
    </visual>
    <collision>
      <geometry>
        <sphere radius="0"/>
      </geometry>
    </collision>
  </link>

  <joint name="core_to_lf_rotation" type="revolute">
    <parent link="core"/>
    <child link="lf_dummy"/>
    <origin xyz="-0.20 0 -0.25"/>
    <axis xyz="0 1 0"/>
    <limit lower="-0.05" upper="0.785398" velocity="100" effort="10"/>
  </joint>

  <joint name="core_to_lf_extension" type="prismatic">
    <parent link="lf_dummy"/>
    <child link="lf"/>
    <origin xyz="0 0 0"/>
    <axis xyz="0 0 -1"/>
    <limit lower="0.45" upper="0.9" velocity="100" effort="20"/>
  </joint>


</robot>


